2020-01-10 19:28:17,052 INFO: Microblog startup [in /home/o4eretniy/PyProject/flask_microblog/app/__init__.py:43]
2020-01-10 19:29:54,864 ERROR: Exception on /edit_profile [POST] [in /home/o4eretniy/.local/lib/python2.7/site-packages/flask/app.py:1891]
Traceback (most recent call last):
  File "/home/o4eretniy/.local/lib/python2.7/site-packages/flask/app.py", line 2446, in wsgi_app
    response = self.full_dispatch_request()
  File "/home/o4eretniy/.local/lib/python2.7/site-packages/flask/app.py", line 1951, in full_dispatch_request
    rv = self.handle_user_exception(e)
  File "/home/o4eretniy/.local/lib/python2.7/site-packages/flask/app.py", line 1820, in handle_user_exception
    reraise(exc_type, exc_value, tb)
  File "/home/o4eretniy/.local/lib/python2.7/site-packages/flask/app.py", line 1949, in full_dispatch_request
    rv = self.dispatch_request()
  File "/home/o4eretniy/.local/lib/python2.7/site-packages/flask/app.py", line 1935, in dispatch_request
    return self.view_functions[rule.endpoint](**req.view_args)
  File "/home/o4eretniy/.local/lib/python2.7/site-packages/flask_login/utils.py", line 261, in decorated_view
    return func(*args, **kwargs)
  File "/home/o4eretniy/PyProject/flask_microblog/app/routes.py", line 63, in edit_profile
    if form.validate_on_submit():
  File "/home/o4eretniy/.local/lib/python2.7/site-packages/flask_wtf/form.py", line 101, in validate_on_submit
    return self.is_submitted() and self.validate()
  File "/home/o4eretniy/.local/lib/python2.7/site-packages/wtforms/form.py", line 310, in validate
    return super(Form, self).validate(extra)
  File "/home/o4eretniy/.local/lib/python2.7/site-packages/wtforms/form.py", line 152, in validate
    if not field.validate(self, extra):
  File "/home/o4eretniy/.local/lib/python2.7/site-packages/wtforms/fields/core.py", line 206, in validate
    stop_validation = self._run_validation_chain(form, chain)
  File "/home/o4eretniy/.local/lib/python2.7/site-packages/wtforms/fields/core.py", line 226, in _run_validation_chain
    validator(form, self)
  File "/home/o4eretniy/PyProject/flask_microblog/app/forms.py", line 41, in validate_username
    user. User.query.filter_by(username=self.username.data).first()
NameError: global name 'user' is not defined
2020-01-10 19:31:11,666 INFO: Microblog startup [in /home/o4eretniy/PyProject/flask_microblog/app/__init__.py:43]
2020-01-10 20:39:38,153 INFO: Microblog startup [in /home/o4eretniy/PyProject/flask_microblog/app/__init__.py:43]
2020-01-10 20:39:49,546 INFO: Microblog startup [in /home/o4eretniy/PyProject/flask_microblog/app/__init__.py:43]
