2020-01-10 19:28:17,052 INFO: Microblog startup [in /home/o4eretniy/PyProject/flask_microblog/app/__init__.py:43]
2020-01-10 19:29:54,864 ERROR: Exception on /edit_profile [POST] [in /home/o4eretniy/.local/lib/python2.7/site-packages/flask/app.py:1891]
Traceback (most recent call last):
  File "/home/o4eretniy/.local/lib/python2.7/site-packages/flask/app.py", line 2446, in wsgi_app
    response = self.full_dispatch_request()
  File "/home/o4eretniy/.local/lib/python2.7/site-packages/flask/app.py", line 1951, in full_dispatch_request
    rv = self.handle_user_exception(e)
  File "/home/o4eretniy/.local/lib/python2.7/site-packages/flask/app.py", line 1820, in handle_user_exception
    reraise(exc_type, exc_value, tb)
  File "/home/o4eretniy/.local/lib/python2.7/site-packages/flask/app.py", line 1949, in full_dispatch_request
    rv = self.dispatch_request()
  File "/home/o4eretniy/.local/lib/python2.7/site-packages/flask/app.py", line 1935, in dispatch_request
    return self.view_functions[rule.endpoint](**req.view_args)
  File "/home/o4eretniy/.local/lib/python2.7/site-packages/flask_login/utils.py", line 261, in decorated_view
    return func(*args, **kwargs)
  File "/home/o4eretniy/PyProject/flask_microblog/app/routes.py", line 63, in edit_profile
    if form.validate_on_submit():
  File "/home/o4eretniy/.local/lib/python2.7/site-packages/flask_wtf/form.py", line 101, in validate_on_submit
    return self.is_submitted() and self.validate()
  File "/home/o4eretniy/.local/lib/python2.7/site-packages/wtforms/form.py", line 310, in validate
    return super(Form, self).validate(extra)
  File "/home/o4eretniy/.local/lib/python2.7/site-packages/wtforms/form.py", line 152, in validate
    if not field.validate(self, extra):
  File "/home/o4eretniy/.local/lib/python2.7/site-packages/wtforms/fields/core.py", line 206, in validate
    stop_validation = self._run_validation_chain(form, chain)
  File "/home/o4eretniy/.local/lib/python2.7/site-packages/wtforms/fields/core.py", line 226, in _run_validation_chain
    validator(form, self)
  File "/home/o4eretniy/PyProject/flask_microblog/app/forms.py", line 41, in validate_username
    user. User.query.filter_by(username=self.username.data).first()
NameError: global name 'user' is not defined
2020-01-10 19:31:11,666 INFO: Microblog startup [in /home/o4eretniy/PyProject/flask_microblog/app/__init__.py:43]
2020-01-10 20:39:38,153 INFO: Microblog startup [in /home/o4eretniy/PyProject/flask_microblog/app/__init__.py:43]
2020-01-10 20:39:49,546 INFO: Microblog startup [in /home/o4eretniy/PyProject/flask_microblog/app/__init__.py:43]
2020-01-16 21:21:10,204 INFO: Microblog startup [in /home/o4eretniy/PyProject/flask_microblog/app/__init__.py:45]
2020-01-16 21:22:45,647 INFO: Microblog startup [in /home/o4eretniy/PyProject/flask_microblog/app/__init__.py:45]
2020-01-16 21:24:06,576 ERROR: Exception on /reset_password_request [POST] [in /home/o4eretniy/.local/lib/python2.7/site-packages/flask/app.py:1891]
Traceback (most recent call last):
  File "/home/o4eretniy/.local/lib/python2.7/site-packages/flask/app.py", line 2446, in wsgi_app
    response = self.full_dispatch_request()
  File "/home/o4eretniy/.local/lib/python2.7/site-packages/flask/app.py", line 1951, in full_dispatch_request
    rv = self.handle_user_exception(e)
  File "/home/o4eretniy/.local/lib/python2.7/site-packages/flask/app.py", line 1820, in handle_user_exception
    reraise(exc_type, exc_value, tb)
  File "/home/o4eretniy/.local/lib/python2.7/site-packages/flask/app.py", line 1949, in full_dispatch_request
    rv = self.dispatch_request()
  File "/home/o4eretniy/.local/lib/python2.7/site-packages/flask/app.py", line 1935, in dispatch_request
    return self.view_functions[rule.endpoint](**req.view_args)
  File "/home/o4eretniy/PyProject/flask_microblog/app/routes.py", line 149, in reset_password_request
    send_password_reset_email(user)
  File "/home/o4eretniy/PyProject/flask_microblog/app/email.py", line 24, in send_password_reset_email
    user=user, token=token))
  File "/home/o4eretniy/.local/lib/python2.7/site-packages/flask/templating.py", line 138, in render_template
    ctx.app.jinja_env.get_or_select_template(template_name_or_list),
  File "/home/o4eretniy/.local/lib/python2.7/site-packages/jinja2/environment.py", line 869, in get_or_select_template
    return self.get_template(template_name_or_list, parent, globals)
  File "/home/o4eretniy/.local/lib/python2.7/site-packages/jinja2/environment.py", line 830, in get_template
    return self._load_template(name, self.make_globals(globals))
  File "/home/o4eretniy/.local/lib/python2.7/site-packages/jinja2/environment.py", line 804, in _load_template
    template = self.loader.load(self, name, globals)
  File "/home/o4eretniy/.local/lib/python2.7/site-packages/jinja2/loaders.py", line 113, in load
    source, filename, uptodate = self.get_source(environment, name)
  File "/home/o4eretniy/.local/lib/python2.7/site-packages/flask/templating.py", line 60, in get_source
    return self._get_source_fast(environment, template)
  File "/home/o4eretniy/.local/lib/python2.7/site-packages/flask/templating.py", line 89, in _get_source_fast
    raise TemplateNotFound(template)
TemplateNotFound: email/reset_password.hmtl
2020-01-16 21:25:12,897 ERROR: Exception on /reset_password_request [POST] [in /home/o4eretniy/.local/lib/python2.7/site-packages/flask/app.py:1891]
Traceback (most recent call last):
  File "/home/o4eretniy/.local/lib/python2.7/site-packages/flask/app.py", line 2446, in wsgi_app
    response = self.full_dispatch_request()
  File "/home/o4eretniy/.local/lib/python2.7/site-packages/flask/app.py", line 1951, in full_dispatch_request
    rv = self.handle_user_exception(e)
  File "/home/o4eretniy/.local/lib/python2.7/site-packages/flask/app.py", line 1820, in handle_user_exception
    reraise(exc_type, exc_value, tb)
  File "/home/o4eretniy/.local/lib/python2.7/site-packages/flask/app.py", line 1949, in full_dispatch_request
    rv = self.dispatch_request()
  File "/home/o4eretniy/.local/lib/python2.7/site-packages/flask/app.py", line 1935, in dispatch_request
    return self.view_functions[rule.endpoint](**req.view_args)
  File "/home/o4eretniy/PyProject/flask_microblog/app/routes.py", line 149, in reset_password_request
    send_password_reset_email(user)
  File "/home/o4eretniy/PyProject/flask_microblog/app/email.py", line 24, in send_password_reset_email
    user=user, token=token))
  File "/home/o4eretniy/.local/lib/python2.7/site-packages/flask/templating.py", line 138, in render_template
    ctx.app.jinja_env.get_or_select_template(template_name_or_list),
  File "/home/o4eretniy/.local/lib/python2.7/site-packages/jinja2/environment.py", line 869, in get_or_select_template
    return self.get_template(template_name_or_list, parent, globals)
  File "/home/o4eretniy/.local/lib/python2.7/site-packages/jinja2/environment.py", line 830, in get_template
    return self._load_template(name, self.make_globals(globals))
  File "/home/o4eretniy/.local/lib/python2.7/site-packages/jinja2/environment.py", line 804, in _load_template
    template = self.loader.load(self, name, globals)
  File "/home/o4eretniy/.local/lib/python2.7/site-packages/jinja2/loaders.py", line 113, in load
    source, filename, uptodate = self.get_source(environment, name)
  File "/home/o4eretniy/.local/lib/python2.7/site-packages/flask/templating.py", line 60, in get_source
    return self._get_source_fast(environment, template)
  File "/home/o4eretniy/.local/lib/python2.7/site-packages/flask/templating.py", line 89, in _get_source_fast
    raise TemplateNotFound(template)
TemplateNotFound: email/reset_password.hmtl
2020-01-16 21:25:22,805 INFO: Microblog startup [in /home/o4eretniy/PyProject/flask_microblog/app/__init__.py:45]
2020-01-16 21:26:30,472 ERROR: Exception on /reset_password/eyJhbGciOiJIUzI1NiIsInR5cCI6IkpXVCJ9.eyJyZXNldF9wYXNzd29yZCI6NCwiZXhwIjoxNTc5MjAzMzM1LjUxODQ4Nn0.ozJ1-RO3y7w4NCAD2UuEsfy2J4ugcldzNU2rzKVPzSA [GET] [in /home/o4eretniy/.local/lib/python2.7/site-packages/flask/app.py:1891]
Traceback (most recent call last):
  File "/home/o4eretniy/.local/lib/python2.7/site-packages/flask/app.py", line 2446, in wsgi_app
    response = self.full_dispatch_request()
  File "/home/o4eretniy/.local/lib/python2.7/site-packages/flask/app.py", line 1951, in full_dispatch_request
    rv = self.handle_user_exception(e)
  File "/home/o4eretniy/.local/lib/python2.7/site-packages/flask/app.py", line 1820, in handle_user_exception
    reraise(exc_type, exc_value, tb)
  File "/home/o4eretniy/.local/lib/python2.7/site-packages/flask/app.py", line 1949, in full_dispatch_request
    rv = self.dispatch_request()
  File "/home/o4eretniy/.local/lib/python2.7/site-packages/flask/app.py", line 1935, in dispatch_request
    return self.view_functions[rule.endpoint](**req.view_args)
  File "/home/o4eretniy/PyProject/flask_microblog/app/routes.py", line 168, in reset_password
    return render_template('reset_password.html', form=form)
  File "/home/o4eretniy/.local/lib/python2.7/site-packages/flask/templating.py", line 140, in render_template
    ctx.app,
  File "/home/o4eretniy/.local/lib/python2.7/site-packages/flask/templating.py", line 120, in _render
    rv = template.render(context)
  File "/home/o4eretniy/.local/lib/python2.7/site-packages/jinja2/environment.py", line 1008, in render
    return self.environment.handle_exception(exc_info, True)
  File "/home/o4eretniy/.local/lib/python2.7/site-packages/jinja2/environment.py", line 780, in handle_exception
    reraise(exc_type, exc_value, tb)
  File "/home/o4eretniy/PyProject/flask_microblog/app/templates/reset_password.html", line 1, in top-level template code
    {% extends 'base.html' %}
  File "/home/o4eretniy/PyProject/flask_microblog/app/templates/base.html", line 28, in top-level template code
    {% block content %}
  File "/home/o4eretniy/PyProject/flask_microblog/app/templates/reset_password.html", line 10, in block "content"
    {% for error in from.password.errors %}
  File "/home/o4eretniy/.local/lib/python2.7/site-packages/jinja2/environment.py", line 430, in getattr
    return getattr(obj, attribute)
UndefinedError: 'from' is undefined
